Traceback (most recent call last):
  File "/usr/lib/python3.8/genericpath.py", line 19, in exists
    os.stat(path)
FileNotFoundError: [Errno 2] No such file or directory: '/home/workspace/.local/lib/python3.8/site-packages/cmake-3.26.3.dist-info/namespace_packages.txt'

During handling of the above exception, another exception occurred:

Traceback (most recent call last):
  File "/usr/local/bin/accelergy", line 5, in <module>
    from accelergy.accelergy_console import main
  File "/usr/local/lib/python3.8/dist-packages/accelergy/accelergy_console.py", line 34, in <module>
    from accelergy.io import parse_commandline_args, generate_output_files
  File "/usr/local/lib/python3.8/dist-packages/accelergy/io.py", line 25, in <module>
    import pyfiglet
  File "/usr/local/lib/python3.8/dist-packages/pyfiglet/__init__.py", line 11, in <module>
    import pkg_resources
  File "/usr/lib/python3/dist-packages/pkg_resources/__init__.py", line 3254, in <module>
    def _initialize_master_working_set():
  File "/usr/lib/python3/dist-packages/pkg_resources/__init__.py", line 3237, in _call_aside
    f(*args, **kwargs)
  File "/usr/lib/python3/dist-packages/pkg_resources/__init__.py", line 3279, in _initialize_master_working_set
    tuple(
  File "/usr/lib/python3/dist-packages/pkg_resources/__init__.py", line 3280, in <genexpr>
    dist.activate(replace=False)
  File "/usr/lib/python3/dist-packages/pkg_resources/__init__.py", line 2785, in activate
    for pkg in self._get_metadata('namespace_packages.txt'):
  File "/usr/lib/python3/dist-packages/pkg_resources/__init__.py", line 2768, in _get_metadata
    if self.has_metadata(name):
  File "/usr/lib/python3/dist-packages/pkg_resources/__init__.py", line 1415, in has_metadata
    return self._has(path)
  File "/usr/lib/python3/dist-packages/pkg_resources/__init__.py", line 1605, in _has
    return os.path.exists(path)
  File "/usr/lib/python3.8/genericpath.py", line 19, in exists
    os.stat(path)
KeyboardInterrupt
